2023-03-06 14:05:56.119734: W tensorflow/stream_executor/platform/default/dso_loader.cc:64] Could not load dynamic library 'libcudart.so.11.0'; dlerror: libcudart.so.11.0: cannot open shared object file: No such file or directory; LD_LIBRARY_PATH: /opt/intel/oneapi/vpl/2022.2.0/lib:/opt/intel/oneapi/tbb/2021.7.0/env/../lib/intel64/gcc4.8:/opt/intel/oneapi/mkl/2022.2.0/lib/intel64:/opt/intel/oneapi/itac/2021.7.0/slib:/opt/intel/oneapi/ippcp/2021.6.1/lib/intel64:/opt/intel/oneapi/ipp/2021.6.1/lib/intel64:/opt/intel/oneapi/dnnl/2022.2.0/cpu_dpcpp_gpu_dpcpp/lib:/opt/intel/oneapi/debugger/2021.7.0/gdb/intel64/lib:/opt/intel/oneapi/debugger/2021.7.0/libipt/intel64/lib:/opt/intel/oneapi/debugger/2021.7.0/dep/lib:/opt/intel/oneapi/dal/2021.7.0/lib/intel64:/opt/intel/oneapi/compiler/2022.2.0/linux/lib:/opt/intel/oneapi/compiler/2022.2.0/linux/lib/x64:/opt/intel/oneapi/compiler/2022.2.0/linux/lib/oclfpga/host/linux64/lib:/opt/intel/oneapi/compiler/2022.2.0/linux/compiler/lib/intel64_lin:/opt/intel/oneapi/ccl/2021.7.0/lib/cpu_gpu_dpcpp:/home/ryan.raikman/miniconda3/lib/
2023-03-06 14:05:56.119786: I tensorflow/stream_executor/cuda/cudart_stub.cc:29] Ignore above cudart dlerror if you do not have a GPU set up on your machine.
2023-03-06 14:06:04.640726: W tensorflow/stream_executor/platform/default/dso_loader.cc:64] Could not load dynamic library 'libcuda.so.1'; dlerror: libcuda.so.1: cannot open shared object file: No such file or directory; LD_LIBRARY_PATH: /opt/intel/oneapi/vpl/2022.2.0/lib:/opt/intel/oneapi/tbb/2021.7.0/env/../lib/intel64/gcc4.8:/opt/intel/oneapi/mkl/2022.2.0/lib/intel64:/opt/intel/oneapi/itac/2021.7.0/slib:/opt/intel/oneapi/ippcp/2021.6.1/lib/intel64:/opt/intel/oneapi/ipp/2021.6.1/lib/intel64:/opt/intel/oneapi/dnnl/2022.2.0/cpu_dpcpp_gpu_dpcpp/lib:/opt/intel/oneapi/debugger/2021.7.0/gdb/intel64/lib:/opt/intel/oneapi/debugger/2021.7.0/libipt/intel64/lib:/opt/intel/oneapi/debugger/2021.7.0/dep/lib:/opt/intel/oneapi/dal/2021.7.0/lib/intel64:/opt/intel/oneapi/compiler/2022.2.0/linux/lib:/opt/intel/oneapi/compiler/2022.2.0/linux/lib/x64:/opt/intel/oneapi/compiler/2022.2.0/linux/lib/oclfpga/host/linux64/lib:/opt/intel/oneapi/compiler/2022.2.0/linux/compiler/lib/intel64_lin:/opt/intel/oneapi/ccl/2021.7.0/lib/cpu_gpu_dpcpp:/home/ryan.raikman/miniconda3/lib/
2023-03-06 14:06:04.640854: W tensorflow/stream_executor/cuda/cuda_driver.cc:269] failed call to cuInit: UNKNOWN ERROR (303)
2023-03-06 14:06:04.640880: I tensorflow/stream_executor/cuda/cuda_diagnostics.cc:156] kernel driver does not appear to be running on this host (ldas-pcdev1): /proc/driver/nvidia/version does not exist
2023-03-06 14:06:04.641338: I tensorflow/core/platform/cpu_feature_guard.cc:193] This TensorFlow binary is optimized with oneAPI Deep Neural Network Library (oneDNN) to use the following CPU instructions in performance-critical operations:  AVX2 FMA
To enable them in other operations, rebuild TensorFlow with the appropriate compiler flags.
WARNING:tensorflow:No training configuration found in the save file, so the model was *not* compiled. Compile it manually.
WARNING:tensorflow:No training configuration found in the save file, so the model was *not* compiled. Compile it manually.
WARNING:tensorflow:No training configuration found in the save file, so the model was *not* compiled. Compile it manually.
WARNING:tensorflow:No training configuration found in the save file, so the model was *not* compiled. Compile it manually.
loaded data shape (2, 884, 12288)
loaded signal shape, (884, 12288, 2)
data segment input shape (884, 12288, 2)
N slices, 2437
going to make it to,  12285
after slice, (884, 2437, 100, 2)
into quak prediction
datae in 33,  (884, 2437, 100, 2)
DATA SHAPE (2154308, 2, 100)
std vals shape (2154308, 2)
now data shape: (2154308, 2, 100)
20, QUAK_vals shape (884, 2437, 4)
22, after smoothing (884, 2388, 4)
Traceback (most recent call last):
  File "/home/ryan.raikman/s22/forks/gw-anomaly/libs/evaluation/anomaly/evaluation/detector_statistic_analysis/eval_metric_on_data.py", line 209, in <module>
    main(data_path, model_savedir, "bbh_kurther_katya_v3")
  File "/home/ryan.raikman/s22/forks/gw-anomaly/libs/evaluation/anomaly/evaluation/detector_statistic_analysis/eval_metric_on_data.py", line 99, in main
    axs[2].plot(katya_metricv2(QUAK_vals[ind]))
NameError: name 'katya_metricv2' is not defined
